<?xml version="1.0" encoding="UTF-8"?>
<!-- Generated by org.testng.reporters.JUnitXMLReporter -->
<testsuite hostname="cty" ignored="0" name="Test" tests="4" failures="2" timestamp="09 五月 2018 17:29:26 GMT" time="0.084" errors="0">
  <testcase name="test1" time="0.041" classname="pri.study.report.AssertLog">
    <failure type="java.lang.AssertionError" message="expected [2] but found [1]">
      <![CDATA[java.lang.AssertionError: expected [2] but found [1]
at pri.study.report.AssertLog.test1(AssertLog.java:10)
... Removed 31 stack frames]]>
    </failure>
  </testcase> <!-- test1 -->
  <testcase name="test2" time="0.001" classname="pri.study.report.AssertLog"/>
  <testcase name="test3" time="0.002" classname="pri.study.report.AssertLog"/>
  <testcase name="logDemo" time="0.001" classname="pri.study.report.AssertLog">
    <failure type="java.lang.RuntimeException" message="运行时抛出异常">
      <![CDATA[java.lang.RuntimeException: 运行时抛出异常
at pri.study.report.AssertLog.logDemo(AssertLog.java:23)
... Removed 25 stack frames]]>
    </failure>
  </testcase> <!-- logDemo -->
</testsuite> <!-- Test -->
